<?xml version="1.0" encoding="utf-8"?>
<!-- This URDF was automatically created by SolidWorks to URDF Exporter! Originally created by Stephen Brawner (brawner@gmail.com) 
     Commit Version: 1.6.0-4-g7f85cfe  Build Version: 1.6.7995.38578
     For more information, please see http://wiki.ros.org/sw_urdf_exporter -->
<robot name="wheel_leg">
<mujoco>
  <compiler
  meshdir=""
  balanceinertia="true"
  discardvisual="false" />
</mujoco>  

<link name="world"></link>
<joint name="floating_base_joint" type="floating">
  <parent link="world" />
  <child link="base_link" />
</joint> 

  <!-- 这部分是urdf的连杆关节描述 -->
  <!-- link -->
  <link name="base_link">
    <inertial>
      <origin xyz="0.01131 -0.0013618 -0.00028518" rpy="0 0 0" />
      <!-- <mass value="2.9637" /> -->
      <mass value="10.9637" />
      <inertia ixx="0.032877" ixy="7.66E-06" ixz="0.0013225" iyy="0.022941" iyz="-1.903E-05" izz="0.041458" />
    </inertial>
    <visual>
      <origin xyz="0 0 0" rpy="0 0 0" />
      <geometry>
        <mesh filename="../meshes/base_link.STL" />
      </geometry>
      <material name="">
        <color rgba="1 1 1 1" />
      </material>
    </visual>
    <collision>
      <origin xyz="0 0 0" rpy="0 0 0" />
      <geometry>
        <mesh filename="../meshes/base_link.STL" />
      </geometry>
    </collision>
  </link>

  <link name="right_hip_link">
    <inertial>
      <origin xyz="0.020031 0.0032153 0.0036019" rpy="0 0 0" />
      <mass value="0.51378" />
      <inertia ixx="0.00053799" ixy="-3.71E-05" ixz="-0.00023837" iyy="0.0015906" iyz="-3.414E-05" izz="0.0015943" />
    </inertial>
    <visual>
      <origin xyz="0 0 0" rpy="0 0 0" />
      <geometry>
        <mesh filename="../meshes/right_hip_link.STL" />
      </geometry>
      <material name="">
        <color rgba="1 1 1 1" />
      </material>
    </visual>
    <collision>
      <origin xyz="0 0 0" rpy="0 0 0" />
      <geometry>
        <mesh filename="../meshes/right_hip_link.STL" />
      </geometry>
    </collision>
  </link>

  <link name="right_knee_link">
    <inertial>
      <origin xyz="0.072881 0.034135 0.019602" rpy="0 0 0" />
      <mass value="0.27188" />
      <inertia ixx="0.00060818" ixy="-0.00045096" ixz="-0.00016097" iyy="0.0018646" iyz="0.00017552" izz="0.0022898" />
    </inertial>
    <visual>
      <origin xyz="0 0 0" rpy="0 0 0" />
      <geometry>
        <mesh filename="../meshes/right_knee_link.STL" />
      </geometry>
      <material name="">
        <color rgba="0.79216 0.81961 0.93333 1" />
      </material>
    </visual>
    <collision>
      <origin xyz="0 0 0" rpy="0 0 0" />
      <geometry>
        <mesh filename="../meshes/right_knee_link.STL" />
      </geometry>
    </collision>
  </link>

  <link name="right_ankle_link">
    <inertial>
      <origin xyz="3.3998E-05 -2.1315E-05 0.046652" rpy="0 0 0" />
      <mass value="1.3401" />
      <inertia ixx="0.0034313" ixy="1.05E-06" ixz="3.9E-07" iyy="0.0034305" iyz="-3.7E-07" izz="0.0062845" />
    </inertial>
    <visual>
      <origin xyz="0 0 0" rpy="0 0 0" />
      <geometry>
        <mesh filename="../meshes/right_ankle_link.STL" />
      </geometry>
      <material name="">
        <color rgba="1 1 1 1" />
      </material>
    </visual>
    <collision>
      <origin xyz="0 0 0" rpy="0 0 0" />
      <geometry>
        <mesh filename="../meshes/right_ankle_link.STL" />
      </geometry>
    </collision>
  </link>

  <link name="left_hip_link">
    <inertial>
      <origin xyz="0.019888 -0.0032269 0.0036874" rpy="0 0 0" />
      <mass value="0.51183" />
      <inertia ixx="0.00053571" ixy="3.735E-05" ixz="-0.00023627" iyy="0.0015772" iyz="3.397E-05" izz="0.0015814" />
    </inertial>
    <visual>
      <origin xyz="0 0 0" rpy="0 0 0" />
      <geometry>
        <mesh filename="../meshes/left_hip_link.STL" />
      </geometry>
      <material name="">
        <color rgba="1 1 1 1" />
      </material>
    </visual>
    <collision>
      <origin xyz="0 0 0" rpy="0 0 0" />
      <geometry>
        <mesh filename="../meshes/left_hip_link.STL" />
      </geometry>
    </collision>
  </link>

  <link name="left_knee_link">
    <inertial>
      <origin xyz="0.073104 -0.034096 0.019634" rpy="0 0 0" />
      <mass value="0.27057" />
      <inertia ixx="0.00060605" ixy="0.00044968" ixz="-0.00016124" iyy="0.0018598" iyz="-0.00017532" izz="0.0022833" />
    </inertial>
    <visual>
      <origin xyz="0 0 0" rpy="0 0 0" />
      <geometry>
        <mesh filename="../meshes/left_knee_link.STL" />
      </geometry>
      <material name="">
        <color rgba="0.79216 0.81961 0.93333 1" />
      </material>
    </visual>
    <collision>
      <origin xyz="0 0 0" rpy="0 0 0" />
      <geometry>
        <mesh filename="../meshes/left_knee_link.STL" />
      </geometry>
    </collision>
  </link>

  <link name="left_ankle_link">
    <inertial>
      <origin xyz="-1.783E-05 -3.5948E-05 0.046652" rpy="0 0 0" />
      <mass value="1.3401" />
      <inertia ixx="0.0034303" ixy="-9.5E-07" ixz="-3.3E-07" iyy="0.0034315" iyz="-4.2E-07" izz="0.0062845" />
    </inertial>
    <visual>
      <origin xyz="0 0 0" rpy="0 0 0" />
      <geometry>
        <mesh filename="../meshes/left_ankle_link.STL" />
      </geometry>
      <material name="">
        <color rgba="1 1 1 1" />
      </material>
    </visual>
    <collision>
      <origin xyz="0 0 0" rpy="0 0 0" />
      <geometry>
        <mesh filename="../meshes/left_ankle_link.STL" />
      </geometry>
    </collision>
  </link>

  <!-- joint -->
  <joint name="right_thigh_joint" type="revolute">
    <origin xyz="-0.001 -0.1785 -0.025" rpy="1.5708 0.34907 0" />
    <parent link="base_link" />
    <child link="right_hip_link" />
    <axis xyz="0 0 -1" />
    <limit lower="-3.14" upper="3.14" effort="20" velocity="6.5" />
    <dynamics damping="1" friction="0.5" />
    <!-- <dynamics damping="0" friction="0" /> -->
  </joint>

  <joint name="right_calf_joint" type="revolute">
    <origin xyz="0.15 0 0" rpy="0 0 -1.6581" />
    <parent link="right_hip_link" />
    <child link="right_knee_link" />
    <axis xyz="0 0 -1" />
    <limit lower="-3.14" upper="3.14" effort="20" velocity="6.5" />
    <dynamics damping="2" friction="0.5" />
    <!-- <dynamics damping="0" friction="0" /> -->
  </joint>

  <joint name="right_wheel_joint" type="continuous">
    <origin xyz="0.25 0 0" rpy="0 0 2.0071" />
    <parent link="right_knee_link" />
    <child link="right_ankle_link" />
    <axis xyz="0 0 -1" />
    <limit effort="20" velocity="500" />
    <dynamics damping="0" friction="0.0" />
  </joint>

  <joint name="left_thigh_joint" type="revolute">
    <origin xyz="-0.00099957 0.1765 -0.024999" rpy="-1.5708 0.34907 0" />
    <parent link="base_link" />
    <child link="left_hip_link" />
    <axis xyz="0 0 1" />
    <limit lower="-3.14" upper="3.14" effort="20" velocity="6.5" />
    <dynamics damping="1" friction="0.5" />
    <!-- <dynamics damping="0" friction="0" /> -->
  </joint>

  <joint name="left_calf_joint" type="revolute">
    <origin xyz="0.15 0 0" rpy="0 0 1.6581" />
    <parent link="left_hip_link" />
    <child link="left_knee_link" />
    <axis xyz="0 0 1" />
    <limit lower="-3.14" upper="3.14" effort="20" velocity="6.5" />
    <dynamics damping="2" friction="0.5" />
    <!-- <dynamics damping="0" friction="0" /> -->
  </joint>

  <joint name="left_wheel_joint" type="continuous">
    <origin xyz="0.25 0 0" rpy="0 0 -2.0071" />
    <parent link="left_knee_link" />
    <child link="left_ankle_link" />
    <axis xyz="0 0 1" />
    <limit effort="20" velocity="500" />
    <dynamics damping="0" friction="0.0" />
  </joint>
 
</robot>
