<mujoco model="wheel_leg">
    <compiler angle="radian" />
    <size njmax="500" nconmax="100" />
    <asset>
        <mesh name="base_link" file="base_link.STL" />
        <mesh name="right_hip_link" file="right_hip_link.STL" />
        <mesh name="right_knee_link" file="right_knee_link.STL" />
        <mesh name="right_ankle_link" file="right_ankle_link.STL" />
        <mesh name="left_hip_link" file="left_hip_link.STL" />
        <mesh name="left_knee_link" file="left_knee_link.STL" />
        <mesh name="left_ankle_link" file="left_ankle_link.STL" />
    </asset>
    <worldbody>
        <body name="base_link" pos="0 0 0">
            <inertial pos="0.01131 -0.0013618 -0.00028518" quat="0.535439 0.536448 -0.46127 0.461257" mass="10.9637" diaginertia="0.0416572 0.0326778 0.022941" />
            <joint name="floating_base_joint" type="free" />
            <geom type="mesh" contype="0" conaffinity="0" group="1" rgba="1 1 1 1" mesh="base_link" />
            <geom type="mesh" rgba="1 1 1 1" mesh="base_link" />
            <body name="right_hip_link" pos="-0.001 -0.1785 -0.025" quat="0.696363 0.696365 0.122789 -0.122789">
                <inertial pos="0.020031 0.0032153 0.0036019" quat="-0.159914 0.619348 -0.104256 0.761555" mass="0.51378" diaginertia="0.00165587 0.00158204 0.000484982" />
                <joint name="right_thigh_joint" pos="0 0 0" axis="0 0 -1" limited="true" range="-3.14 3.14" damping="1" frictionloss="0.5" />
                <geom type="mesh" contype="0" conaffinity="0" group="1" rgba="1 1 1 1" mesh="right_hip_link" />
                <geom type="mesh" rgba="1 1 1 1" mesh="right_hip_link" />
                <body name="right_knee_link" pos="0.15 0 0" quat="0.675576 0 0 -0.73729">
                    <inertial pos="0.072881 0.034135 0.019602" quat="0.0687246 0.633523 0.266631 0.723072" mass="0.27188" diaginertia="0.00158753 0.00158753 0.00158753" />
                    <joint name="right_calf_joint" pos="0 0 0" axis="0 0 -1" limited="true" range="-3.14 3.14" damping="2" frictionloss="0.5" />
                    <geom type="mesh" contype="0" conaffinity="0" group="1" rgba="0.79216 0.81961 0.93333 1" mesh="right_knee_link" />
                    <geom type="mesh" rgba="0.79216 0.81961 0.93333 1" mesh="right_knee_link" />
                    <body name="right_ankle_link" pos="0.25 0 0" quat="0.537312 0 0 0.843384">
                        <inertial pos="3.3998e-05 -2.1315e-05 0.046652" quat="0.328821 0.626055 -0.328857 0.625927" mass="1.3401" diaginertia="0.0062845 0.00343202 0.00342978" />
                        <joint name="right_wheel_joint" pos="0 0 0" axis="0 0 -1" />
                        <geom type="mesh" contype="0" conaffinity="0" group="1" rgba="1 1 1 1" mesh="right_ankle_link" />
                        <geom type="mesh" rgba="1 1 1 1" mesh="right_ankle_link" />
                    </body>
                </body>
            </body>
            <body name="left_hip_link" pos="-0.00099957 0.1765 -0.024999" quat="0.696363 -0.696365 0.122789 0.122789">
                <inertial pos="0.019888 -0.0032269 0.0036874" quat="0.159128 0.619428 0.103202 0.761798" mass="0.51183" diaginertia="0.00164241 0.00156884 0.00048306" />
                <joint name="left_thigh_joint" pos="0 0 0" axis="0 0 1" limited="true" range="-3.14 3.14" damping="1" frictionloss="0.5" />
                <geom type="mesh" contype="0" conaffinity="0" group="1" rgba="1 1 1 1" mesh="left_hip_link" />
                <geom type="mesh" rgba="1 1 1 1" mesh="left_hip_link" />
                <body name="left_knee_link" pos="0.15 0 0" quat="0.675576 0 0 0.73729">
                    <inertial pos="0.073104 -0.034096 0.019634" quat="-0.069104 0.633333 -0.266758 0.723155" mass="0.27057" diaginertia="0.00158305 0.00158305 0.00158305" />
                    <joint name="left_calf_joint" pos="0 0 0" axis="0 0 1" limited="true" range="-3.14 3.14" damping="2" frictionloss="0.5" />
                    <geom type="mesh" contype="0" conaffinity="0" group="1" rgba="0.79216 0.81961 0.93333 1" mesh="left_knee_link" />
                    <geom type="mesh" rgba="0.79216 0.81961 0.93333 1" mesh="left_knee_link" />
                    <body name="left_ankle_link" pos="0.25 0 0" quat="0.537312 0 0 -0.843384">
                        <inertial pos="-1.783e-05 -3.5948e-05 0.046652" quat="-0.176268 0.684742 0.176187 0.684847" mass="1.3401" diaginertia="0.0062845 0.00343202 0.00342978" />
                        <joint name="left_wheel_joint" pos="0 0 0" axis="0 0 1" />
                        <geom type="mesh" contype="0" conaffinity="0" group="1" rgba="1 1 1 1" mesh="left_ankle_link" />
                        <geom type="mesh" rgba="1 1 1 1" mesh="left_ankle_link" />
                    </body>
                </body>
            </body>
        </body>
    </worldbody>
</mujoco>
